{
 "cells": [
  {
   "cell_type": "code",
   "execution_count": 1,
   "id": "643e642d",
   "metadata": {},
   "outputs": [],
   "source": [
    "from numpy import expand_dims\n",
    "from tensorflow.keras.preprocessing.image import load_img\n",
    "from tensorflow.keras.preprocessing.image import img_to_array\n",
    "from tensorflow.keras.preprocessing.image import ImageDataGenerator\n",
    "from matplotlib import pyplot\n",
    "import os\n",
    "from os import walk\n",
    "from PIL import Image\n",
    "from numpy import shape\n",
    "import cv2\n",
    "import numpy as np\n",
    "from matplotlib import cm"
   ]
  },
  {
   "cell_type": "code",
   "execution_count": 11,
   "id": "80e76063",
   "metadata": {},
   "outputs": [
    {
     "name": "stdout",
     "output_type": "stream",
     "text": [
      "ERROR! Session/line number was not unique in database. History logging moved to new session 203\n"
     ]
    }
   ],
   "source": [
    "def shiftImage(img, counter, path, sampleNo, graphs = False):\n",
    "\n",
    "    # convert to numpy array\n",
    "    data = img_to_array(img)\n",
    "    \n",
    "    # expand dimension to one sample\n",
    "    samples = expand_dims(data, 0)\n",
    "    \n",
    "    # create image data augmentation generator\n",
    "    datagen = ImageDataGenerator(width_shift_range=0.2, height_shift_range=0.2)\n",
    "    \n",
    "    # prepare iterator\n",
    "    it = datagen.flow(samples, batch_size=1)\n",
    "    \n",
    "    # generate samples and plot\n",
    "    for i in range(sampleNo):\n",
    "        \n",
    "        if graphs == True:\n",
    "            # define subplot\n",
    "            pyplot.subplot(330 + 1 + i)\n",
    "        \n",
    "        # generate batch of images\n",
    "        batch = it.next()\n",
    "\n",
    "        # convert to unsigned integers for viewing\n",
    "        image = batch[0].astype('uint8')\n",
    "        \n",
    "        if graphs == True:\n",
    "            # plot raw pixel data\n",
    "            pyplot.imshow(image,cmap='gray')\n",
    "        \n",
    "        image = np.reshape(image,(32,32))\n",
    "        \n",
    "        image = Image.fromarray(image, 'L')\n",
    "        #image.save(path+\"\\\\\"+str(counter)+\".jpg\")\n",
    "        counter += 1\n",
    "    pyplot.show()\n",
    "    return counter"
   ]
  },
  {
   "cell_type": "code",
   "execution_count": 12,
   "id": "bd5a2e0f",
   "metadata": {},
   "outputs": [],
   "source": [
    "def rotateImage(img, counter, path, sampleNo, graphs = False):\n",
    "\n",
    "    # convert to numpy array\n",
    "    data = img_to_array(img)\n",
    "    \n",
    "    # expand dimension to one sample\n",
    "    samples = expand_dims(data, 0)\n",
    "    \n",
    "    # create image data augmentation generator\n",
    "    datagen = ImageDataGenerator(rotation_range=45)\n",
    "    \n",
    "    # prepare iterator\n",
    "    it = datagen.flow(samples, batch_size=1)\n",
    "    \n",
    "    # generate samples and plot\n",
    "    for i in range(9):\n",
    "        \n",
    "        if graphs == True:\n",
    "            # define subplot\n",
    "            pyplot.subplot(330 + 1 + i)\n",
    "        \n",
    "        # generate batch of images\n",
    "        batch = it.next()\n",
    "\n",
    "        # convert to unsigned integers for viewing\n",
    "        image = batch[0].astype('uint8')\n",
    "        \n",
    "        if graphs == True:\n",
    "            # plot raw pixel data\n",
    "            pyplot.imshow(image,cmap='gray')\n",
    "            \n",
    "        image = np.reshape(image,(32,32))\n",
    "        \n",
    "        image = Image.fromarray(image, 'L')\n",
    "        #image.save(path+\"\\\\\"+str(counter)+\".jpg\")\n",
    "        counter += 1\n",
    "    pyplot.show()\n",
    "    return counter"
   ]
  },
  {
   "cell_type": "code",
   "execution_count": 63,
   "id": "f6fa3063",
   "metadata": {},
   "outputs": [],
   "source": [
    "def main():\n",
    "    os.mkdir(\"Characters\\\\JPEGAugmented\\\\\")\n",
    "    os.mkdir(\"Characters\\\\JPEGAugmented\\\\Shifted\\\\\")\n",
    "    os.mkdir(\"Characters\\\\JPEGAugmented\\\\FinalData\\\\\")\n",
    "    \n",
    "    subfolders = [ f.path for f in os.scandir(\"Characters\\JPEGResized\") if f.is_dir() ]\n",
    "\n",
    "    for subfolder in subfolders:\n",
    "        \n",
    "        _, _, filenames = next(walk(subfolder))\n",
    "        counter = 0\n",
    "        splitName = str(subfolder).split(\"\\\\\")\n",
    "        os.mkdir(\"Characters\\\\JPEGAugmented\\\\Shifted\\\\\"+splitName[2])\n",
    "        \n",
    "        for filename in filenames:\n",
    "            image = cv2.imread(subfolder+\"\\\\\"+filename, cv2.IMREAD_UNCHANGED)\n",
    "            path  = \"Characters\\\\JPEGAugmented\\\\Shifted\\\\\"+splitName[2]\n",
    "            counter = shiftImage(image,counter,path, 10)\n",
    "            \n",
    "    print(\"Vertical and Horizontal Shifts Done!\")\n",
    "    \n",
    "    subfolders = [ f.path for f in os.scandir(\"Characters\\JPEGAugmented\\Shifted\") if f.is_dir() ]\n",
    "    \n",
    "    for subfolder in subfolders:\n",
    "        \n",
    "        _, _, filenames = next(walk(subfolder))\n",
    "        counter = 0\n",
    "        splitName = str(subfolder).split(\"\\\\\")\n",
    "        os.mkdir(\"Characters\\\\JPEGAugmented\\\\FinalData\\\\\"+splitName[3])\n",
    "        \n",
    "        for filename in filenames:\n",
    "            image = cv2.imread(subfolder+\"\\\\\"+filename, cv2.IMREAD_UNCHANGED)\n",
    "            #print(image.shape)\n",
    "            path  = \"Characters\\\\JPEGAugmented\\\\FinalData\\\\\"+splitName[3]\n",
    "            counter = rotateImage(image,counter,path, 10)\n",
    "            \n",
    "    print(\"Rotations Done!\")\n",
    "    print(\"Data Augmentation Complete!!!\")"
   ]
  },
  {
   "cell_type": "code",
   "execution_count": 64,
   "id": "5ac8167e",
   "metadata": {},
   "outputs": [
    {
     "name": "stdout",
     "output_type": "stream",
     "text": [
      "Vertical and Horizontal Shifts Done!\n",
      "Rotations Done!\n",
      "Data Augmentation Complete!!!\n"
     ]
    }
   ],
   "source": [
    "main()"
   ]
  },
  {
   "cell_type": "code",
   "execution_count": null,
   "id": "0082f5ab",
   "metadata": {},
   "outputs": [
    {
     "name": "stderr",
     "output_type": "stream",
     "text": [
      "ERROR:root:Internal Python error in the inspect module.\n",
      "Below is the traceback from this internal error.\n",
      "\n",
      "ERROR:root:Internal Python error in the inspect module.\n",
      "Below is the traceback from this internal error.\n",
      "\n",
      "ERROR:root:Internal Python error in the inspect module.\n",
      "Below is the traceback from this internal error.\n",
      "\n"
     ]
    },
    {
     "name": "stdout",
     "output_type": "stream",
     "text": [
      "Traceback (most recent call last):\n",
      "  File \"C:\\Users\\Roger\\anaconda3\\envs\\ml\\lib\\site-packages\\IPython\\core\\interactiveshell.py\", line 3437, in run_code\n",
      "    exec(code_obj, self.user_global_ns, self.user_ns)\n",
      "  File \"<ipython-input-13-e40bca6a0c71>\", line 2, in <module>\n",
      "    counter = rotateImage(image,0,\"\\\\Test\", 10, True)\n",
      "TypeError: rotateImage() takes 4 positional arguments but 5 were given\n",
      "\n",
      "During handling of the above exception, another exception occurred:\n",
      "\n",
      "Traceback (most recent call last):\n",
      "  File \"C:\\Users\\Roger\\anaconda3\\envs\\ml\\lib\\site-packages\\IPython\\core\\interactiveshell.py\", line 2061, in showtraceback\n",
      "    stb = value._render_traceback_()\n",
      "AttributeError: 'TypeError' object has no attribute '_render_traceback_'\n",
      "\n",
      "During handling of the above exception, another exception occurred:\n",
      "\n",
      "Traceback (most recent call last):\n",
      "  File \"C:\\Users\\Roger\\anaconda3\\envs\\ml\\lib\\site-packages\\IPython\\core\\ultratb.py\", line 1101, in get_records\n",
      "    return _fixed_getinnerframes(etb, number_of_lines_of_context, tb_offset)\n",
      "  File \"C:\\Users\\Roger\\anaconda3\\envs\\ml\\lib\\site-packages\\IPython\\core\\ultratb.py\", line 248, in wrapped\n",
      "    return f(*args, **kwargs)\n",
      "  File \"C:\\Users\\Roger\\anaconda3\\envs\\ml\\lib\\site-packages\\IPython\\core\\ultratb.py\", line 281, in _fixed_getinnerframes\n",
      "    records = fix_frame_records_filenames(inspect.getinnerframes(etb, context))\n",
      "  File \"C:\\Users\\Roger\\anaconda3\\envs\\ml\\lib\\inspect.py\", line 1495, in getinnerframes\n",
      "    frameinfo = (tb.tb_frame,) + getframeinfo(tb, context)\n",
      "  File \"C:\\Users\\Roger\\anaconda3\\envs\\ml\\lib\\inspect.py\", line 1453, in getframeinfo\n",
      "    filename = getsourcefile(frame) or getfile(frame)\n",
      "  File \"C:\\Users\\Roger\\anaconda3\\envs\\ml\\lib\\inspect.py\", line 696, in getsourcefile\n",
      "    if getattr(getmodule(object, filename), '__loader__', None) is not None:\n",
      "  File \"C:\\Users\\Roger\\anaconda3\\envs\\ml\\lib\\inspect.py\", line 733, in getmodule\n",
      "    if ismodule(module) and hasattr(module, '__file__'):\n",
      "  File \"C:\\Users\\Roger\\anaconda3\\envs\\ml\\lib\\site-packages\\tensorflow\\__init__.py\", line 50, in __getattr__\n",
      "    module = self._load()\n",
      "  File \"C:\\Users\\Roger\\anaconda3\\envs\\ml\\lib\\site-packages\\tensorflow\\__init__.py\", line 44, in _load\n",
      "    module = _importlib.import_module(self.__name__)\n",
      "  File \"C:\\Users\\Roger\\anaconda3\\envs\\ml\\lib\\importlib\\__init__.py\", line 127, in import_module\n",
      "    return _bootstrap._gcd_import(name[level:], package, level)\n",
      "  File \"<frozen importlib._bootstrap>\", line 1006, in _gcd_import\n",
      "  File \"<frozen importlib._bootstrap>\", line 983, in _find_and_load\n",
      "  File \"<frozen importlib._bootstrap>\", line 965, in _find_and_load_unlocked\n",
      "ModuleNotFoundError: No module named 'tensorflow_core.estimator'\n",
      "ERROR! Session/line number was not unique in database. History logging moved to new session 204\n",
      "Traceback (most recent call last):\n",
      "  File \"C:\\Users\\Roger\\anaconda3\\envs\\ml\\lib\\site-packages\\IPython\\core\\interactiveshell.py\", line 3437, in run_code\n",
      "    exec(code_obj, self.user_global_ns, self.user_ns)\n",
      "  File \"<ipython-input-13-e40bca6a0c71>\", line 2, in <module>\n",
      "    counter = rotateImage(image,0,\"\\\\Test\", 10, True)\n",
      "TypeError: rotateImage() takes 4 positional arguments but 5 were given\n",
      "\n",
      "During handling of the above exception, another exception occurred:\n",
      "\n",
      "Traceback (most recent call last):\n",
      "  File \"C:\\Users\\Roger\\anaconda3\\envs\\ml\\lib\\site-packages\\IPython\\core\\interactiveshell.py\", line 2061, in showtraceback\n",
      "    stb = value._render_traceback_()\n",
      "AttributeError: 'TypeError' object has no attribute '_render_traceback_'\n",
      "\n",
      "During handling of the above exception, another exception occurred:\n",
      "\n",
      "Traceback (most recent call last):\n",
      "  File \"C:\\Users\\Roger\\anaconda3\\envs\\ml\\lib\\site-packages\\IPython\\core\\interactiveshell.py\", line 3357, in run_ast_nodes\n",
      "    if (await self.run_code(code, result,  async_=asy)):\n",
      "  File \"C:\\Users\\Roger\\anaconda3\\envs\\ml\\lib\\site-packages\\IPython\\core\\interactiveshell.py\", line 3454, in run_code\n",
      "    self.showtraceback(running_compiled_code=True)\n",
      "  File \"C:\\Users\\Roger\\anaconda3\\envs\\ml\\lib\\site-packages\\IPython\\core\\interactiveshell.py\", line 2064, in showtraceback\n",
      "    value, tb, tb_offset=tb_offset)\n",
      "  File \"C:\\Users\\Roger\\anaconda3\\envs\\ml\\lib\\site-packages\\IPython\\core\\ultratb.py\", line 1368, in structured_traceback\n",
      "    self, etype, value, tb, tb_offset, number_of_lines_of_context)\n",
      "  File \"C:\\Users\\Roger\\anaconda3\\envs\\ml\\lib\\site-packages\\IPython\\core\\ultratb.py\", line 1268, in structured_traceback\n",
      "    self, etype, value, tb, tb_offset, number_of_lines_of_context\n",
      "  File \"C:\\Users\\Roger\\anaconda3\\envs\\ml\\lib\\site-packages\\IPython\\core\\ultratb.py\", line 1125, in structured_traceback\n",
      "    tb_offset)\n",
      "  File \"C:\\Users\\Roger\\anaconda3\\envs\\ml\\lib\\site-packages\\IPython\\core\\ultratb.py\", line 1082, in format_exception_as_a_whole\n",
      "    last_unique, recursion_repeat = find_recursion(orig_etype, evalue, records)\n",
      "  File \"C:\\Users\\Roger\\anaconda3\\envs\\ml\\lib\\site-packages\\IPython\\core\\ultratb.py\", line 382, in find_recursion\n",
      "    return len(records), 0\n",
      "TypeError: object of type 'NoneType' has no len()\n",
      "\n",
      "During handling of the above exception, another exception occurred:\n",
      "\n",
      "Traceback (most recent call last):\n",
      "  File \"C:\\Users\\Roger\\anaconda3\\envs\\ml\\lib\\site-packages\\IPython\\core\\interactiveshell.py\", line 2061, in showtraceback\n",
      "    stb = value._render_traceback_()\n",
      "AttributeError: 'TypeError' object has no attribute '_render_traceback_'\n",
      "\n",
      "During handling of the above exception, another exception occurred:\n",
      "\n",
      "Traceback (most recent call last):\n",
      "  File \"C:\\Users\\Roger\\anaconda3\\envs\\ml\\lib\\site-packages\\IPython\\core\\ultratb.py\", line 1101, in get_records\n",
      "    return _fixed_getinnerframes(etb, number_of_lines_of_context, tb_offset)\n",
      "  File \"C:\\Users\\Roger\\anaconda3\\envs\\ml\\lib\\site-packages\\IPython\\core\\ultratb.py\", line 248, in wrapped\n",
      "    return f(*args, **kwargs)\n",
      "  File \"C:\\Users\\Roger\\anaconda3\\envs\\ml\\lib\\site-packages\\IPython\\core\\ultratb.py\", line 281, in _fixed_getinnerframes\n",
      "    records = fix_frame_records_filenames(inspect.getinnerframes(etb, context))\n",
      "  File \"C:\\Users\\Roger\\anaconda3\\envs\\ml\\lib\\inspect.py\", line 1495, in getinnerframes\n",
      "    frameinfo = (tb.tb_frame,) + getframeinfo(tb, context)\n",
      "  File \"C:\\Users\\Roger\\anaconda3\\envs\\ml\\lib\\inspect.py\", line 1453, in getframeinfo\n",
      "    filename = getsourcefile(frame) or getfile(frame)\n",
      "  File \"C:\\Users\\Roger\\anaconda3\\envs\\ml\\lib\\inspect.py\", line 696, in getsourcefile\n",
      "    if getattr(getmodule(object, filename), '__loader__', None) is not None:\n",
      "  File \"C:\\Users\\Roger\\anaconda3\\envs\\ml\\lib\\inspect.py\", line 733, in getmodule\n",
      "    if ismodule(module) and hasattr(module, '__file__'):\n",
      "  File \"C:\\Users\\Roger\\anaconda3\\envs\\ml\\lib\\site-packages\\tensorflow\\__init__.py\", line 50, in __getattr__\n",
      "    module = self._load()\n",
      "  File \"C:\\Users\\Roger\\anaconda3\\envs\\ml\\lib\\site-packages\\tensorflow\\__init__.py\", line 44, in _load\n",
      "    module = _importlib.import_module(self.__name__)\n",
      "  File \"C:\\Users\\Roger\\anaconda3\\envs\\ml\\lib\\importlib\\__init__.py\", line 127, in import_module\n",
      "    return _bootstrap._gcd_import(name[level:], package, level)\n",
      "  File \"<frozen importlib._bootstrap>\", line 1006, in _gcd_import\n",
      "  File \"<frozen importlib._bootstrap>\", line 983, in _find_and_load\n",
      "  File \"<frozen importlib._bootstrap>\", line 965, in _find_and_load_unlocked\n",
      "ModuleNotFoundError: No module named 'tensorflow_core.estimator'\n",
      "Traceback (most recent call last):\n",
      "  File \"C:\\Users\\Roger\\anaconda3\\envs\\ml\\lib\\site-packages\\IPython\\core\\interactiveshell.py\", line 3437, in run_code\n",
      "    exec(code_obj, self.user_global_ns, self.user_ns)\n",
      "  File \"<ipython-input-13-e40bca6a0c71>\", line 2, in <module>\n",
      "    counter = rotateImage(image,0,\"\\\\Test\", 10, True)\n",
      "TypeError: rotateImage() takes 4 positional arguments but 5 were given\n",
      "\n",
      "During handling of the above exception, another exception occurred:\n",
      "\n",
      "Traceback (most recent call last):\n",
      "  File \"C:\\Users\\Roger\\anaconda3\\envs\\ml\\lib\\site-packages\\IPython\\core\\interactiveshell.py\", line 2061, in showtraceback\n",
      "    stb = value._render_traceback_()\n",
      "AttributeError: 'TypeError' object has no attribute '_render_traceback_'\n",
      "\n",
      "During handling of the above exception, another exception occurred:\n",
      "\n",
      "Traceback (most recent call last):\n",
      "  File \"C:\\Users\\Roger\\anaconda3\\envs\\ml\\lib\\site-packages\\IPython\\core\\interactiveshell.py\", line 3357, in run_ast_nodes\n",
      "    if (await self.run_code(code, result,  async_=asy)):\n",
      "  File \"C:\\Users\\Roger\\anaconda3\\envs\\ml\\lib\\site-packages\\IPython\\core\\interactiveshell.py\", line 3454, in run_code\n",
      "    self.showtraceback(running_compiled_code=True)\n",
      "  File \"C:\\Users\\Roger\\anaconda3\\envs\\ml\\lib\\site-packages\\IPython\\core\\interactiveshell.py\", line 2064, in showtraceback\n",
      "    value, tb, tb_offset=tb_offset)\n",
      "  File \"C:\\Users\\Roger\\anaconda3\\envs\\ml\\lib\\site-packages\\IPython\\core\\ultratb.py\", line 1368, in structured_traceback\n",
      "    self, etype, value, tb, tb_offset, number_of_lines_of_context)\n",
      "  File \"C:\\Users\\Roger\\anaconda3\\envs\\ml\\lib\\site-packages\\IPython\\core\\ultratb.py\", line 1268, in structured_traceback\n",
      "    self, etype, value, tb, tb_offset, number_of_lines_of_context\n",
      "  File \"C:\\Users\\Roger\\anaconda3\\envs\\ml\\lib\\site-packages\\IPython\\core\\ultratb.py\", line 1125, in structured_traceback\n",
      "    tb_offset)\n",
      "  File \"C:\\Users\\Roger\\anaconda3\\envs\\ml\\lib\\site-packages\\IPython\\core\\ultratb.py\", line 1082, in format_exception_as_a_whole\n",
      "    last_unique, recursion_repeat = find_recursion(orig_etype, evalue, records)\n",
      "  File \"C:\\Users\\Roger\\anaconda3\\envs\\ml\\lib\\site-packages\\IPython\\core\\ultratb.py\", line 382, in find_recursion\n",
      "    return len(records), 0\n",
      "TypeError: object of type 'NoneType' has no len()\n",
      "\n",
      "During handling of the above exception, another exception occurred:\n",
      "\n",
      "Traceback (most recent call last):\n",
      "  File \"C:\\Users\\Roger\\anaconda3\\envs\\ml\\lib\\site-packages\\IPython\\core\\interactiveshell.py\", line 2061, in showtraceback\n",
      "    stb = value._render_traceback_()\n",
      "AttributeError: 'TypeError' object has no attribute '_render_traceback_'\n",
      "\n",
      "During handling of the above exception, another exception occurred:\n",
      "\n",
      "Traceback (most recent call last):\n",
      "  File \"C:\\Users\\Roger\\anaconda3\\envs\\ml\\lib\\site-packages\\IPython\\core\\interactiveshell.py\", line 2940, in _run_cell\n",
      "    return runner(coro)\n",
      "  File \"C:\\Users\\Roger\\anaconda3\\envs\\ml\\lib\\site-packages\\IPython\\core\\async_helpers.py\", line 68, in _pseudo_sync_runner\n",
      "    coro.send(None)\n",
      "  File \"C:\\Users\\Roger\\anaconda3\\envs\\ml\\lib\\site-packages\\IPython\\core\\interactiveshell.py\", line 3166, in run_cell_async\n",
      "    interactivity=interactivity, compiler=compiler, result=result)\n",
      "  File \"C:\\Users\\Roger\\anaconda3\\envs\\ml\\lib\\site-packages\\IPython\\core\\interactiveshell.py\", line 3376, in run_ast_nodes\n",
      "    self.showtraceback()\n",
      "  File \"C:\\Users\\Roger\\anaconda3\\envs\\ml\\lib\\site-packages\\IPython\\core\\interactiveshell.py\", line 2064, in showtraceback\n",
      "    value, tb, tb_offset=tb_offset)\n",
      "  File \"C:\\Users\\Roger\\anaconda3\\envs\\ml\\lib\\site-packages\\IPython\\core\\ultratb.py\", line 1368, in structured_traceback\n",
      "    self, etype, value, tb, tb_offset, number_of_lines_of_context)\n",
      "  File \"C:\\Users\\Roger\\anaconda3\\envs\\ml\\lib\\site-packages\\IPython\\core\\ultratb.py\", line 1268, in structured_traceback\n",
      "    self, etype, value, tb, tb_offset, number_of_lines_of_context\n",
      "  File \"C:\\Users\\Roger\\anaconda3\\envs\\ml\\lib\\site-packages\\IPython\\core\\ultratb.py\", line 1143, in structured_traceback\n",
      "    chained_exceptions_tb_offset)\n",
      "  File \"C:\\Users\\Roger\\anaconda3\\envs\\ml\\lib\\site-packages\\IPython\\core\\ultratb.py\", line 1082, in format_exception_as_a_whole\n",
      "    last_unique, recursion_repeat = find_recursion(orig_etype, evalue, records)\n",
      "  File \"C:\\Users\\Roger\\anaconda3\\envs\\ml\\lib\\site-packages\\IPython\\core\\ultratb.py\", line 382, in find_recursion\n",
      "    return len(records), 0\n",
      "TypeError: object of type 'NoneType' has no len()\n",
      "\n",
      "During handling of the above exception, another exception occurred:\n",
      "\n",
      "Traceback (most recent call last):\n",
      "  File \"C:\\Users\\Roger\\anaconda3\\envs\\ml\\lib\\site-packages\\IPython\\core\\interactiveshell.py\", line 2061, in showtraceback\n",
      "    stb = value._render_traceback_()\n",
      "AttributeError: 'TypeError' object has no attribute '_render_traceback_'\n",
      "\n",
      "During handling of the above exception, another exception occurred:\n",
      "\n",
      "Traceback (most recent call last):\n",
      "  File \"C:\\Users\\Roger\\anaconda3\\envs\\ml\\lib\\site-packages\\IPython\\core\\ultratb.py\", line 1101, in get_records\n",
      "    return _fixed_getinnerframes(etb, number_of_lines_of_context, tb_offset)\n",
      "  File \"C:\\Users\\Roger\\anaconda3\\envs\\ml\\lib\\site-packages\\IPython\\core\\ultratb.py\", line 248, in wrapped\n",
      "    return f(*args, **kwargs)\n",
      "  File \"C:\\Users\\Roger\\anaconda3\\envs\\ml\\lib\\site-packages\\IPython\\core\\ultratb.py\", line 281, in _fixed_getinnerframes\n",
      "    records = fix_frame_records_filenames(inspect.getinnerframes(etb, context))\n",
      "  File \"C:\\Users\\Roger\\anaconda3\\envs\\ml\\lib\\inspect.py\", line 1495, in getinnerframes\n",
      "    frameinfo = (tb.tb_frame,) + getframeinfo(tb, context)\n",
      "  File \"C:\\Users\\Roger\\anaconda3\\envs\\ml\\lib\\inspect.py\", line 1453, in getframeinfo\n",
      "    filename = getsourcefile(frame) or getfile(frame)\n",
      "  File \"C:\\Users\\Roger\\anaconda3\\envs\\ml\\lib\\inspect.py\", line 696, in getsourcefile\n",
      "    if getattr(getmodule(object, filename), '__loader__', None) is not None:\n",
      "  File \"C:\\Users\\Roger\\anaconda3\\envs\\ml\\lib\\inspect.py\", line 733, in getmodule\n",
      "    if ismodule(module) and hasattr(module, '__file__'):\n",
      "  File \"C:\\Users\\Roger\\anaconda3\\envs\\ml\\lib\\site-packages\\tensorflow\\__init__.py\", line 50, in __getattr__\n",
      "    module = self._load()\n",
      "  File \"C:\\Users\\Roger\\anaconda3\\envs\\ml\\lib\\site-packages\\tensorflow\\__init__.py\", line 44, in _load\n",
      "    module = _importlib.import_module(self.__name__)\n",
      "  File \"C:\\Users\\Roger\\anaconda3\\envs\\ml\\lib\\importlib\\__init__.py\", line 127, in import_module\n",
      "    return _bootstrap._gcd_import(name[level:], package, level)\n",
      "  File \"<frozen importlib._bootstrap>\", line 1006, in _gcd_import\n",
      "  File \"<frozen importlib._bootstrap>\", line 983, in _find_and_load\n",
      "  File \"<frozen importlib._bootstrap>\", line 965, in _find_and_load_unlocked\n",
      "ModuleNotFoundError: No module named 'tensorflow_core.estimator'\n"
     ]
    }
   ],
   "source": [
    "image = cv2.imread(\"0.jpg\", cv2.IMREAD_UNCHANGED)\n",
    "counter = rotateImage(image,0,\"\\\\Test\", 10, True)"
   ]
  },
  {
   "cell_type": "code",
   "execution_count": null,
   "id": "a1d6b233",
   "metadata": {},
   "outputs": [],
   "source": []
  }
 ],
 "metadata": {
  "kernelspec": {
   "display_name": "Python 3",
   "language": "python",
   "name": "python3"
  },
  "language_info": {
   "codemirror_mode": {
    "name": "ipython",
    "version": 3
   },
   "file_extension": ".py",
   "mimetype": "text/x-python",
   "name": "python",
   "nbconvert_exporter": "python",
   "pygments_lexer": "ipython3",
   "version": "3.7.0"
  }
 },
 "nbformat": 4,
 "nbformat_minor": 5
}
